## 예외 발생시키기

키워드 throw를 이용해 고의로 예외 발생시킬 수 있음

1. 먼저, 연산자 new를 이용하여 발생시키려는 예외 클래스의 객체를 만들고
    
    Exception e = new Exeption(”고의로 발생시킨 예외”);
    
2. 키워드 throw를 이용해 예외를 발생시킨다
    
    throw e;
    

Exception 인스턴스 생성 시, 생성자에 String을 넣어주면, Exception 인스턴스 메시지로 저장됨.  
→ getMessage()를 이용해 얻을 수 있음

예외 처리가 되어야 할 부분에 예외 처리가 되어있지 않다면, unreported Excpetion 이라는 컴파일 에러를 마주하게 됨.  
(+ unchecked예외인 RuntimeException의 경우에는 컴파일 에러는 나지 않음)

## 메서드에 예외 선언하기

try-catch문 말고도, 메서드에 예외를 선언하는 방법도 있음

메서드의 선언부에 throws를 이용해 발생할 수 있는 예외를 적어주면 됨(+ 여러 개면 쉼표로 구분)

```java
void method() throws Exception1, Exception2, ... , ExceptionN {
	// 메서드 내용
}
```

(다른 많은 언어들과는 달리) 자바에서는 메서드 내에서 발생할 가능성이 있는 예외를  
메서드의 선언부에 명시하여 메서드를 사용하는 쪽에서는 이에 대한 처리를 하도록 강요

→ 프로그래머들의 짐을 덜어줌 + 견고한 프로그램 코드 작성 가능

- 메서드 선언부에 쓰는 예외는 일반적으로 RuntimeException은 적지 않음

    → throws에 선언한다고 해서 문제가 되지는 않지만, 보통 반드시 처리 해줘야 하는 예외들만 선언함

- Java API 문서를 통해 사용하려는 메서드의 선언부와 Throws:를 보고,  
발생할 수 있는 예외와 반드시 처리해야 하는 예외가 무엇인지 확인하는 것이 좋음

### 예외를 메서드의 throws에 명시

→ 예외를 처리하지 않고, 자신을 호출한 메서드에게 예외를 (단순히) 전달하여 떠맡기는 것.

→ 예외를 전달받은 메서드가 또 다시 자신을 호출한 메서드에게 전달할 수도 있으나,  
     제일 마지막에 있는 main에서도 예외가 처리되지 않는다면, 프로그램은 비정상적 종료

→ 어느 한 곳에서는 반드시 try-catch문으로 예외처리 해야 함

## finally블럭

예외 발생여부에 상관없이 실행 되어야할 코드를 포함시킬 목적으로 사용됨.

try-catch-finally 순서로 구성

```java
try {
	// 예외가 발생할 가능성이 있는 문장들
} catch (Exception1 e1) {
	// 예외 처리를 위한 문장들
} finally {
	// 예외 발생 여부와 관계없이 항상 수행되어야하는 문장들
	// finally 블럭은 try-catch 문의 맨 마지막에 위치해야 함
}
```

- 예외 발생    : try → catch → finally
- 예외 발생 X : try → finally

만약 try문 안에 return  문이 실행되는 경우에도
finally 블럭의 문장들까지 모두 실행된 후에, 현재 메서드 종료됨

마찬가지로, catch블럭 실행 도중 return문이 있더라도, finally블럭의 문장은 수행된 후 종료

## 자동 자원 반환 - try-with-resources문

JDK1.7부터 새로운 변형이 추가됨

사용 후 꼭 닫아줘야 하는 것들이 있는 입출력 클래스를 사용할 때 유용함

```java
try {
	fis = new FileInputStream("score.dat");
	dis = new DataInputStream(fis);
// ...
} catch (IOException ie) {
	ie.printStackTrace();
} finally {
	// dis.close(); 이런 방법도 있지만, close()가 예외를 발생시키기도 하기 때문에
	try {
		if(dis != null)
			dis.close();
	} catch(IOException ie) {           // try블럭과 finally 블럭에서 모두 예외가 발생하면,
		ie.printStackTrace();       // try블럭의 예외는 무시된다는 또 다른 문제점 발생
	}
}
```

try-with-resources 문으로 바꾸면,

```java
// 괄호 () 안에 두 문장 이상 넣을 경우 ';'로 구분한다

try (FileInputStream fis = new FileInputStream("score.dat");
		 DataInputStream dis = new DataInputStream(fis)) {
	while(true) {
		score = dis.readInt();
		System.out.println(score);
		sum += score;
	}
} catch (EOFxception e) {
	System.out.println("점수의 총합은 " + sum + "입니다.");
} catch (IOException ie) {
	ie.printStackTrace();
}
```

- try-catch-resources 문의 괄호()안에 객체를 생성하는 문장을 넣으면,
이 객체는 따로 호출하지 않아도 try 블럭을 벗어나는 순간 자동적으로 close()가 호출됨  
→ 그 이후 catch 블럭 또는 finally 블럭이 수행됨
- 자동으로 close()가 호출되는 객체는 클래스가 AutoCloseable이라는 인터페이스를 구현한 것이어야만 함
- 만약 try문 내부와 close() 둘 다에서 예외가 발생한다면
    - 두 예외가 동시에 발생할 수는 없기 때문에,
        - 실제 발생한 예외는 일반적으로 출력하고,
        - CloseException은 ‘supressed’(억제된) 키워드와 함께 출력됨

Throwable에는 억제된 예외와 관련된 다음과 같은 메서드가 정의되어 있음

```java
void addSupressed(Throwable exception)        억제된 예외를 추가
Throwable[] getSupressed()                    억제된 예외(배열)를 반환
```

## 사용자정의 예외 만들기

(기존에 정의된 예외 클래스 외) 프로그래머가 새로운 예외 클래스 정의 가능함

보통 Exception클래스 혹은 RuntimeException 클래스로부터 상속받아 클래스를 만들지만,  
필요에 따라 알맞은 예외 클래스를 선택 가능

```java
class MyException extends Exception {
	MyException(String msg) {       // 문자열을 매개변수로 받는 생성자
		super(msg);             // 조상인 Exception 클래스의 생성자를 호출
	}
}
```

```java
class MyException extends Exception {

	// 에러 코드 값을 저장하기 위한 필드 추가
	private final int ERR_CODE;  // 생성자를 통해 초기화

	MyException(String msg, int errCode) {
		super(msg);
		ERR_CODE = errCode;
	}
	MyException(String msg) {           // 생성자
		this(msg, 100);             // ERR_CODE를 100(기본값으로 초기화)
	}

	// 에러 코드를 얻을 수 있는 메서드도 추가함
	public int getErrCode() {
		return ERR_CODE;
	}
}
```

기존에는 주로 Exception을 상속받아 ‘checked 예외’로 작성하는 경우가 많았지만,

요즘은 예외처리를 선택적으로 할 수 있도록 RuntimeException 상속받아 작성하는 쪽으로 바뀌는 중

## 예외 되던지기(exception re-throwing)

한 메서드에서 발생한 예외에 대해서 **예외가 발생한 메서드**와 **호출한 메서드**, 양쪽에 나눠 처리 가능

- 예외를 처리한 후 인위적으로 다시 발생시키는 방법
    
    → 예외 되던지기(exception re-throwing)
    
    - 예외가 발생할 메서드에 try-catch문으로 예외처리 + 메서드 선언부에 발생할 예외 지정

```java
static int method1() throws Exception { // 예외 선언 반드시 필요
	try {
		System.out.println("method1이 호출됨");
		return 0;                           // 현재 실행중인 메서드 종료
	} catch (Exception e) {
		e.printStackTrace();
	      //return 1;                           // catch 블럭 내에도 return문 필요함
		throw new Exception();              // return문 대신 예외를 호출한 메서드로 전달
	} finally {
		System.out.println("method1()의 finally 블럭이 실행됨");
	}
}
```

## 연결된 예외(chained exception)

한 예외가 다른 예외를 발생시키는 것.  
예외 A가 예외 B를 발생시켰다면, A를 B의 원인 예외(cause exception)라고 함  
initCause()는 Exception클래스의 조상인 Throwable클래스에 정의되어 있기에 모든 예외에 사용가능

```java
Throwable initCause(Throwable cause)      지정한 예외를 원인 예외로 등록
Throwable getCause()                      원인 예외를 반환   
```

```java
try {
	startInstall();     // SpaceException 발생
	copyFiles();
} catch (SpaceException e) {
	InstallException ie = new InstallException("설치중 예외발생"); // 예외 생성
	ie.initCause(e);    // InstallException의 원인 예외를 SpaceException으로 지정
	throw ie;           // InstallException을 발생시킨다
} catch (MemoryException me) {
	// ...
}
```

발생한 예외를 그냥 처리하지 않고, 원인 예외로 등록하여 다시 예외로 발생시키는 이유?  
→ 여러 가지 예외를 하나의 큰 분류의 예외로 묶어 다루기 위함

(두 예외가 상속 관계가 아니어도 관계X)

```java
static void install() throws InstallException {
	try {
		startInstall();
		copyFiles();
	} catch (SpaceException se)
		InstallException ie = new InstallException("설치 중 예외 발생");
		ie.initCause(se);
		throw ie;
	} catch (MemoryException me)
		InstallException ie = new InstallException("설치 중 예외 발생");
		ie.initCause(me);
		throw ie;
	}
}
```

→ checked 예외를 unchecked 예외로 바꾸기 위함

```java
static void startInstall() throws SpaceException, MemoryException {
	if(!enoughSpace())
		throw new SpaceException("설치 공간이 부족");
	
	if(!enoughMemory())
		throw new MemoryException("메모리가 부족");
}
```

이 코드를, 아래처럼 변환 가능

```java
static void startInstall() throws SpaceException {
	if(!enoughSpace())
		throw new SpaceException("설치 공간이 부족");
	
	if(!enoughMemory())
		throw new RuntimeException(new MemoryException("메모리가 부족"));
}
```

MemoryException은 Exception의 자손, 반드시 예외처리 해야하지만  
→ RuntimeException으로 감쌌기 때문에 선언부에 MemoryException 선언할 필요 X
